<!--
Copyright (c) 2020 Philipp Moritz, The dm_control Authors

Use of this source code is governed by an MIT-style
license that can be found in the LICENSE file or at
https://opensource.org/licenses/MIT.
-->
<mujoco model="ant">
  <compiler angle="degree"/>
  <default>
    <motor ctrlrange="-1.0 1.0" ctrllimited="true" gear="75"/>
    <geom friction="1 0.5 0.5" solref=".02 1" solimp="0 .8 .01" material="self" density="50.0"/>
    <joint limited="true" armature="1" damping="1" stiffness="1" solreflimit=".04 1" solimplimit="0 .8 .03"/>
    <default class="rangefinder">
        <site type="capsule" size=".05 .5" rgba="1 0 0 .4" group="4"/>
    </default>
  </default>
  <asset>
    <material name="self" rgba=".8 .6 .4 1"/>
  </asset>
  <worldbody>
    <camera name="sideon" pos="0 -10 5" fovy="45" mode="targetbody" target="seg0" />
    <camera name="float_far"  pos="-4 0 2" xyaxes="0 -1 0 .5 0 1" mode="trackcom" fovy="90"/>
    <body name="seg0" pos="1 1 5">
      <camera name="floating"  pos="-2 0 1" xyaxes="0 -1 0 .5 0 1" mode="trackcom" fovy="90"/>
      <camera name="egocentric"  pos=".25 0 .11" xyaxes="0 -1 0 0 0 1" fovy="90" />

      <site name="seg0_touch" type="box" size="0.26 0.26 0.26" rgba="0 0 1 1" group="4"/>
      <geom name="seg0_geom" type="box" pos="0 0 0" size="0.7817855 0.436341643 1.3171674" euler="19.852272 164.862534 256.7119" rgba="1 1 0 0"/>
      <site name="seg0_site" size="0.05" rgba="1 0 0 1"/>

      <site name="rf_xp" class="rangefinder" pos="0.25 0 0.11" zaxis="1 0 0"/>
      <site name="rf_xn" class="rangefinder" pos="-0.25 0 0.11" zaxis="-1 0 0"/>
      <site name="rf_yp" class="rangefinder" pos="0 0.25 0.11"  zaxis="0 1 0"/>
      <site name="rf_yn" class="rangefinder" pos="0 -0.25 0.11"  zaxis="0 -1 0"/>
      <site name="rf_xpyp" class="rangefinder" pos="0.25 0.25 0.11" zaxis="1 1 0"/>
      <site name="rf_xpyn" class="rangefinder" pos="0.25 -0.25 0.11"  zaxis="1 -1 0"/>
      <site name="rf_xnyn" class="rangefinder" pos="-0.25 -0.25 0.11" zaxis="-1 -1 0"/>
      <site name="rf_xnyp" class="rangefinder" pos="-0.25 0.25 0.11" zaxis="-1 1 0"/>

      <!-- sites that visualize the x-y axis of the ant body, good for debugging -->
      <site name="x_pos" type="capsule" pos="0.5 0 0" size=".05 .5" zaxis="1 0 0" rgba="1 0 0 1" group="5"/>
      <site name="x_neg" type="capsule" pos="-0.5 0 0" size=".05 .5"  zaxis="-1 0 0" rgba="0 0 1 1"  group="5"/>
      <site name="y_pos" type="capsule" pos="0 0.5 0" size=".05 .5"  zaxis="0 1 0" rgba="1 1 1 1" group="5"/>
      <site name="y_neg" type="capsule" pos="0 -0.5 0" size=".05 .5"  zaxis="0 -1 0" rgba="0 0 0 1" group="5"/>
      <site name="port_site" pos=".5 0 0" size="0.5" rgba="1 0 0 1" group="5"/>
      <site name="starboard_site" pos="-.5 0 0" size="0.5" rgba="0 1 0 1" group="5"/>

      <site name="rc1" type="sphere" size=".1" rgba="1 1 1 1"/>
      <site name="rc2" type="sphere" size=".1" rgba="1 1 1 1"/>
      <site name="rc3" type="sphere" size=".1" rgba="1 1 1 1"/>
      <site name="rc4" type="sphere" size=".1" rgba="1 1 1 1"/>
      <site name="rc5" type="sphere" size=".1" rgba="1 1 1 1"/>
      <site name="rc6" type="sphere" size=".1" rgba="1 1 1 1"/>
      <site name="rc7" type="sphere" size=".1" rgba="1 1 1 1"/>
      <site name="rc8" type="sphere" size=".1" rgba="1 1 1 1"/>
      <site name="rc9" type="sphere" size=".1" rgba="1 1 1 1"/>
      <site name="rc10" type="sphere" size=".1" rgba="1 1 1 1"/>

      <body name="seg1" pos="0.384460345 -0.1082156 1.3215">
        <joint name="seg0_to_1" range="-75 75" type="hinge" axis="0 1 0"/>
        <geom name="seg1_geom" type="box" pos="0 0 0" size="0.595344 0.388579842 0.419512331" euler="351.413818 156.671753 186.149872" rgba="1 1 1 0"/>
        <site name="seg1_site" type="box" pos="0 0 0" size="0.09 0.09 0.24" zaxis="0.2 0.2 0" rgba="1 1 0 0"/>
        <body name="seg2" pos="-0.22067261 -0.5 1.30303946">
          <joint name="seg1_to_2" range="-75 75" type="hinge" axis="0 1 0"/>
          <geom name="seg2_geom" type="box" pos="0 0 0" size="0.165260255 0.482132822 0.5905807" euler="20.4026775 257.081238 240.1416" rgba="1 1 1 0"/>
          <site name="seg2_site" type="box" pos="0.1 0.1 0" size="0.09 0.09 0.24" zaxis="0.2 0.2 0" rgba="1 1 0 0"/>
        </body>
        
      </body>

    </body>
  </worldbody>

  <actuator>
    <motor name="seg0_to_1" joint="seg0_to_1"/>
    <motor name="seg1_to_2" joint="seg1_to_2"/>
  </actuator>

  <sensor>
    <touch name="seg0_touch" site="seg0_touch"/>
    <touch name="seg0_site" site="seg0_site"/>
    <touch name="seg1_site" site="seg1_site"/>
    <touch name="seg2_site" site="seg2_site"/>
    <velocimeter name="torso_vel" site="seg0_site"/>
    <gyro name="torso_gyro" site="seg0_site"/>
    <accelerometer name="torso_accel" site="seg0_site"/>
    <rangefinder name="rf_xp" site="rf_xp"/>
    <rangefinder name="rf_yp" site="rf_yp"/>
    <rangefinder name="rf_xn" site="rf_xn"/>
    <rangefinder name="rf_yn" site="rf_yn"/>
    <rangefinder name="rf_xpyp" site="rf_xpyp"/>
    <rangefinder name="rf_xpyn" site="rf_xpyn"/>
    <rangefinder name="rf_xnyp" site="rf_xnyp"/>
    <rangefinder name="rf_xnyn" site="rf_xnyn"/>
  </sensor>

  <contact>
    <exclude body1="seg0" body2="seg1"/>
    <exclude body1="seg1" body2="seg2"/>
  </contact>
</mujoco>
