<!--
Copyright (c) 2020 Philipp Moritz, The dm_control Authors

Use of this source code is governed by an MIT-style
license that can be found in the LICENSE file or at
https://opensource.org/licenses/MIT.
-->
<mujoco model="ant">
    <compiler angle="degree" />
    <default>
        <motor ctrlrange="-1.0 1.0" ctrllimited="true" gear="75" />
        <geom friction="1 0.5 0.5" solref=".02 1" solimp="0 .8 .01" material="self" density="50.0" />
        <joint limited="true" armature="1" damping="1" stiffness="1" solreflimit=".04 1"
            solimplimit="0 .8 .03" />
        <default class="rangefinder">
            <site type="capsule" size=".05 .5" rgba="1 0 0 .4" group="4" />
        </default>
    </default>
    <asset>
        <material name="self" rgba=".8 .6 .4 1" />
    </asset>

    <worldbody>

        <!-- INSERT BODY HERE -->

        <body name="seg0" pos="1 1 5">
			<camera name="egocentric" pos=".25 0 .11" xyaxes="0 -1 0 0 0 1" fovy="90" />
            <site name="seg0_touch" type="box" size="0.26 0.26 0.26" rgba="0 0 1 1" group="4" />
            <geom name="seg0_geom" type="box" pos="0 0 0" size="0.7817855 0.436341643 1.3171674"
                euler="0 0 0" rgba="1 1 0 0" />
            <site name="seg0_site" size="0.05" rgba="1 0 0 1" />

            <body name="seg1" pos="-0.746078492 0.13879776 1.733679731">
                <!-- TODO: check if segments 1 and 2 should have pos argument actually defined, like
                is this just something we missed initially?-->
                <joint name="seg0_to_1" range="-75 75" type="hinge" axis="0 0 1" />
                <geom name="seg1_geom" type="box" pos="0 0 0"
                    size="0.595344 0.388579842 0.419512331"
                    euler="0.0008985509 0.00109280727 0.004466458" rgba="1 1 1 0" />
                <site name="seg1_site" type="box" pos="0 0 0" size="0.09 0.09 0.24"
                    zaxis="0.2 0.2 0" rgba="1 1 0 0" />
            </body>
            <body name="seg2" pos="0.781785488 -0.12621116 -0.419321776">
                <joint name="seg0_to_2" range="-75 75" type="hinge" axis="0 1 0" />
                <geom name="seg2_geom" type="box" pos="0 0 0"
                    size="0.165260255 0.482132822 0.5905807"
                    euler="0.000849346863 0.00307855778 0.0009179028" rgba="1 1 1 0" />
                <site name="seg2_site" type="box" pos="0.1 0.1 0" size="0.09 0.09 0.24"
                    zaxis="0.2 0.2 0" rgba="1 1 0 0" />
                <body name="seg3" pos="-0.080371756 0.48215293 1.013563076">
                    <!-- TODO: check whether instead of multiplying each coordinate by -1, if we can
                    just have -1 instead of 1 in the axis vector instead -->
                    <joint name="seg2_to_3" range="-75 75" type="hinge" axis="0 1 0"
                        pos="0.24 -0.91 -0.49" />
                    <geom name="seg3_geom" type="box" pos="0 0 0"
                        size="0.145482287 0.424432218 0.5199013"
                        euler="0.000849346863 0.00307855778 0.0009179028" rgba="1 1 1 0" />
                    <site name="seg3_site" type="box" pos="0.1 0.1 0" size="0.09 0.09 0.24"
                        zaxis="0.2 0.2 0" rgba="1 1 0 0" />
                </body>
            </body>

            <body name="seg4" pos="0.3417406 0.382444382 2.69673526">
                <joint name="seg0_to_4" range="-75 75" type="hinge" axis="0 1 0"
                    pos="-0.218564168 -1.0 -0.4382396" />
                <geom name="seg4_geom" type="box" pos="0 0 0" size="0.386039972 1.126239 1.37956786"
                    euler="0.0 0.0 0.0" rgba="1 1 1 0" />
                <site name="seg4_site" type="box" pos="0.1 0.1 0" size="0.09 0.09 0.24"
                    zaxis="0.2 0.2 0" rgba="1 1 0 0" />
            </body>


        </body>
    </worldbody>

    <actuator>
        <motor name="seg0_to_1" joint="seg0_to_1" />
        <motor name="seg0_to_2" joint="seg0_to_2" />
        <motor name="seg2_to_3" joint="seg2_to_3" />
    </actuator>

    <sensor>
        <touch name="seg0_touch" site="seg0_touch" />
        <touch name="seg0_site" site="seg0_site" />
        <touch name="seg1_site" site="seg1_site" />
        <touch name="seg2_site" site="seg2_site" />
        <touch name="seg3_site" site="seg3_site" />
        <velocimeter name="torso_vel" site="seg0_site" />
        <gyro name="torso_gyro" site="seg0_site" />
        <accelerometer name="torso_accel" site="seg0_site" />
    </sensor>

    <contact>
        <exclude body1="seg0" body2="seg1" />
        <exclude body1="seg1" body2="seg2" />
        <exclude body1="seg0" body2="seg2" />
        <exclude body1="seg2" body2="seg3" />
        <exclude body1="seg1" body2="seg3" />
        <exclude body1="seg0" body2="seg3" />
    </contact>
</mujoco>