<mujoco model="orn-gigasvermis">
    <!-- GENERATED by rower_soccer/tools/unity2mujoco.py. Do not hand-edit.
         gear_scale=0.03  length_scale=0.1768  density=50
         -> 22.01 kg
         Regenerate:
           python -m rower_soccer.tools.unity2mujoco --input <.creature> \
             --out <this file> --name orn-gigasvermis \
             --gear-scale 0.03 --length-scale 0.1768
         The gear_scale is NOT reconstructible from the XML alone -- an earlier
         worm was checked in at gear_scale=0.03 with that fact recorded nowhere,
         so a later regeneration at the default 1.0 silently made it 33x
         stronger. Hence this header. -->
    <compiler angle="degree" />
    <default>
        <motor ctrlrange="-1.0 1.0" ctrllimited="true" gear="15.6332" />
        <geom friction="1 0.5 0.5" solref=".02 1" solimp="0 .8 .01" material="self" density="50" />
        <joint limited="true" armature="0.000172747" damping="0.000410838" stiffness="0.000977078" solreflimit=".04 1"
            solimplimit="0 .8 .03" />
    </default>
    <asset>
        <material name="self" rgba=".8 .6 .4 1" />
    </asset>

    <worldbody>
        <body name="seg0" pos="0 0 0.2613209">

      <camera name="floating" pos="-2.11 0 1.05" xyaxes="0 -1 0 .5 0 1" mode="trackcom" fovy="70" />
      <camera name="egocentric" pos="0.46 0 .11" xyaxes="0 -1 0 0 0 1" fovy="90" />
          <geom name="seg0_geom" type="box" pos="0 0 0" size="0.1280482 0.1204073 0.2613209" euler="0 0 0" />
          <site name="seg0_site" type="box" pos="0 0 0" size="0.140853 0.132448 0.287453" zaxis="0 0 1" rgba="1 1 0 0.15" />

          <body name="seg1" pos="0.1221998 0.03830071 0.5449345">
            <joint name="seg0_to_1" range="-75 75" type="hinge" axis="0 1 0" pos="-0.08436245 -0.02811942 -0.1768 "/>
            <geom name="seg1_geom" type="box" pos="0 0 0" size="0.1981978 0.2115602 0.2836136" euler="0.004153203 -0.000728891 -0.001950957" />
            <site name="seg1_site" type="box" pos="0 0 0" size="0.2180175 0.2327162 0.3119749" zaxis="0 0 1" rgba="1 1 0 0.15" />

            <body name="seg2" pos="0.1982088 0.1855726 0.530645">
              <joint name="seg1_to_2" range="-75 75" type="hinge" axis="0 1 0" pos="-0.0884 -0.07752818 -0.1223635 "/>
              <geom name="seg2_geom" type="box" pos="0 0 0" size="0.2946969 0.3145653 0.4217002" euler="0.005932046 -0.002004978 -0.0047394" />
              <site name="seg2_site" type="box" pos="0 0 0" size="0.3241666 0.3460218 0.4638702" zaxis="0 0 1" rgba="1 1 0 0.15" />
            </body>
          </body>
        </body>
    </worldbody>

    <actuator>
    <motor name="motor0_to_1" joint="seg0_to_1" gear="66.3688" />
    <motor name="motor1_to_2" joint="seg1_to_2" gear="100.519" />
    </actuator>

    <sensor>
    <touch name="seg0_touch" site="seg0_site" />
    <touch name="seg1_touch" site="seg1_site" />
    <touch name="seg2_touch" site="seg2_site" />
        <velocimeter name="torso_vel" site="seg0_site" />
        <gyro name="torso_gyro" site="seg0_site" />
        <accelerometer name="torso_accel" site="seg0_site" />
    </sensor>

    <contact>
    <exclude body1="seg0" body2="seg1" />
    <exclude body1="seg0" body2="seg2" />
    <exclude body1="seg1" body2="seg2" />
    </contact>
</mujoco>
