<mujoco model="pon-ornispelagus">
    <!-- GENERATED by rower_soccer/tools/unity2mujoco.py. Do not hand-edit.
         gear_scale=0.03  length_scale=0.1768  mass_scale=1
         density=50  total mass 7.278 kg

         Regenerate with python -m rower_soccer.tools.unity2mujoco and flags:
           input=(.creature file)  out=(this file)  name=pon-ornispelagus
           gear-scale=0.03  length-scale=0.1768  mass-scale=1

         gear_scale is NOT reconstructible from the XML alone. An earlier worm
         was checked in at gear_scale=0.03 with that fact recorded nowhere, so
         regenerating at the tool default of 1.0 silently produced a creature
         33x stronger, which compiles and runs and looks plausible. Hence this
         header.

         mass_scale multiplies density, gear, armature, damping and stiffness
         together, which leaves the creature's own motion exactly invariant
         (F = ma: force and mass scale alike) while changing its momentum ratio
         against the fixed-mass ball. Do not scale one without the others.

         (Flags are written as name=value, without their leading dashes: a
         double hyphen cannot appear inside an XML comment. lxml, which
         dm_control's mjcf parser uses, rejects the whole file outright, while
         MuJoCo's own parser accepts it. So a comment containing a doubled dash
         loads fine on the Warp path and blows up only on the CPU eval.) -->
    <compiler angle="degree" />
    <default>
        <motor ctrlrange="-1.0 1.0" ctrllimited="true" gear="15.6332" />
        <geom friction="1 0.5 0.5" solref=".02 1" solimp="0 .8 .01" material="self" density="50" />
        <joint limited="true" armature="0.000172747" damping="0.000410838" stiffness="0.000977078" solreflimit=".04 1"
            solimplimit="0 .8 .03" />
    </default>
    <asset>
        <material name="self" rgba=".8 .6 .4 1" />
    </asset>

    <worldbody>
        <body name="seg0" pos="0 0 0.2328752">

      <camera name="floating" pos="-1.38 0 0.69" xyaxes="0 -1 0 .5 0 1" mode="trackcom" fovy="70" />
      <camera name="egocentric" pos="0.30 0 .11" xyaxes="0 -1 0 0 0 1" fovy="90" />
          <geom name="seg0_geom" type="box" pos="0 0 0" size="0.1382197 0.0771452 0.2328752" euler="0 0 0" />
          <site name="seg0_site" type="box" pos="0 0 0" size="0.1520416 0.08485972 0.2561627" zaxis="0 0 1" rgba="1 1 0 0.15" />

          <body name="seg1" pos="-0.1319067 0.02453935 0.307045">
            <joint name="seg0_to_1" range="-75 75" type="hinge" axis="0 0 1" pos="0.08436245 -0.02811942 -0.1768 "/>
            <geom name="seg1_geom" type="box" pos="0 0 0" size="0.1052568 0.06870091 0.07416978" euler="0.000898551 0.001092807 0.004466458" />
            <site name="seg1_site" type="box" pos="0 0 0" size="0.1157825 0.07557101 0.08158676" zaxis="0 0 1" rgba="1 1 0 0.15" />
          </body>

          <body name="seg2" pos="0.1382197 -0.02231425 -0.07413609">
            <joint name="seg0_to_2" range="-75 75" type="hinge" axis="0 1 0" pos="-0.0884 0.0255697 -0.02062169 "/>
            <geom name="seg2_geom" type="box" pos="0 0 0" size="0.02921801 0.08524108 0.1044147" euler="0.0008493469 0.003078558 0.0009179028" />
            <site name="seg2_site" type="box" pos="0 0 0" size="0.03213982 0.09376519 0.1148561" zaxis="0 0 1" rgba="1 1 0 0.15" />

            <body name="seg3" pos="-0.0142098 0.08524469 0.179198">
              <joint name="seg2_to_3" range="-75 75" type="hinge" axis="0 1 0" pos="0.04299675 -0.0884 -0.1622941 "/>
              <geom name="seg3_geom" type="box" pos="0 0 0" size="0.02572127 0.07503962 0.09191855" euler="0.0008493469 0.003078558 0.0009179028" />
              <site name="seg3_site" type="box" pos="0 0 0" size="0.02829339 0.08254358 0.1011104" zaxis="0 0 1" rgba="1 1 0 0.15" />
            </body>
          </body>

          <body name="seg4" pos="0.06041975 0.06761622 0.4767828">
            <joint name="seg0_to_4" range="-75 75" type="hinge" axis="0 1 0" pos="-0.03864215 -0.07748082 -0.1768 "/>
            <geom name="seg4_geom" type="box" pos="0 0 0" size="0.06825187 0.199119 0.2439076" euler="0 0 0" />
            <site name="seg4_site" type="box" pos="0 0 0" size="0.07507705 0.2190309 0.2682984" zaxis="0 0 1" rgba="1 1 0 0.15" />

            <body name="seg5" pos="0.03319693 0.199119 0.4186012">
              <joint name="seg4_to_5" range="-75 75" type="hinge" axis="0 1 0" pos="-0.04299675 -0.0884 -0.1622941 "/>
              <geom name="seg5_geom" type="box" pos="0 0 0" size="0.06008363 0.1752889 0.2147173" euler="0 0 0" />
              <site name="seg5_site" type="box" pos="0 0 0" size="0.066092 0.1928178 0.236189" zaxis="0 0 1" rgba="1 1 0 0.15" />
            </body>
          </body>

          <body name="seg6" pos="-0.04850844 -0.0771452 0.4628896">
            <joint name="seg0_to_6" range="-75 75" type="hinge" axis="0 1 0" pos="0.03102414 0.0884 -0.1591922 "/>
            <geom name="seg6_geom" type="box" pos="0 0 0" size="0.07734392 0.2256443 0.2763993" euler="0.0009045518 -0.0004349161 -0.004343248" />
            <site name="seg6_site" type="box" pos="0 0 0" size="0.08507831 0.2482088 0.3040393" zaxis="0 0 1" rgba="1 1 0 0.15" />

            <body name="seg7" pos="-0.03758244 0.2256521 0.4743637">
              <joint name="seg6_to_7" range="-75 75" type="hinge" axis="0 1 0" pos="0.04299675 -0.0884 -0.1622941 "/>
              <geom name="seg7_geom" type="box" pos="0 0 0" size="0.06808757 0.1986397 0.2433205" euler="0.0009045518 -0.0004349161 -0.004343248" />
              <site name="seg7_site" type="box" pos="0 0 0" size="0.07489633 0.2185037 0.2676525" zaxis="0 0 1" rgba="1 1 0 0.15" />
            </body>
          </body>

          <body name="seg8" pos="0.1137559 0.0771452 -0.1352829">
            <joint name="seg0_to_8" range="-75 75" type="hinge" axis="0 0 1" pos="-0.07275391 -0.0884 -0.001867963 "/>
            <geom name="seg8_geom" type="box" pos="0 0 0" size="0.1315131 0.08583834 0.09267141" euler="0 0 0" />
            <site name="seg8_site" type="box" pos="0 0 0" size="0.1446644 0.09442217 0.1019386" zaxis="0 0 1" rgba="1 1 0 0.15" />
          </body>
        </body>
    </worldbody>

    <actuator>
    <motor name="motor0_to_1" joint="seg0_to_1" gear="0.0330148" />
    <motor name="motor0_to_2" joint="seg0_to_2" gear="0.0234921" />
    <motor name="motor2_to_3" joint="seg2_to_3" gear="0.0122818" />
    <motor name="motor0_to_4" joint="seg0_to_4" gear="1.64788" />
    <motor name="motor4_to_5" joint="seg4_to_5" gear="0.861523" />
    <motor name="motor0_to_6" joint="seg0_to_6" gear="3.08337" />
    <motor name="motor6_to_7" joint="seg6_to_7" gear="1.61201" />
    <motor name="motor0_to_8" joint="seg0_to_8" gear="0.100756" />
    </actuator>

    <sensor>
    <touch name="seg0_touch" site="seg0_site" />
    <touch name="seg1_touch" site="seg1_site" />
    <touch name="seg2_touch" site="seg2_site" />
    <touch name="seg3_touch" site="seg3_site" />
    <touch name="seg4_touch" site="seg4_site" />
    <touch name="seg5_touch" site="seg5_site" />
    <touch name="seg6_touch" site="seg6_site" />
    <touch name="seg7_touch" site="seg7_site" />
    <touch name="seg8_touch" site="seg8_site" />
        <velocimeter name="torso_vel" site="seg0_site" />
        <gyro name="torso_gyro" site="seg0_site" />
        <accelerometer name="torso_accel" site="seg0_site" />
    </sensor>

    <contact>
    <exclude body1="seg0" body2="seg1" />
    <exclude body1="seg0" body2="seg2" />
    <exclude body1="seg0" body2="seg3" />
    <exclude body1="seg0" body2="seg4" />
    <exclude body1="seg0" body2="seg5" />
    <exclude body1="seg0" body2="seg6" />
    <exclude body1="seg0" body2="seg7" />
    <exclude body1="seg0" body2="seg8" />
    <exclude body1="seg1" body2="seg2" />
    <exclude body1="seg1" body2="seg3" />
    <exclude body1="seg1" body2="seg4" />
    <exclude body1="seg1" body2="seg5" />
    <exclude body1="seg1" body2="seg6" />
    <exclude body1="seg1" body2="seg7" />
    <exclude body1="seg1" body2="seg8" />
    <exclude body1="seg2" body2="seg3" />
    <exclude body1="seg2" body2="seg4" />
    <exclude body1="seg2" body2="seg5" />
    <exclude body1="seg2" body2="seg6" />
    <exclude body1="seg2" body2="seg7" />
    <exclude body1="seg2" body2="seg8" />
    <exclude body1="seg3" body2="seg4" />
    <exclude body1="seg3" body2="seg5" />
    <exclude body1="seg3" body2="seg6" />
    <exclude body1="seg3" body2="seg7" />
    <exclude body1="seg3" body2="seg8" />
    <exclude body1="seg4" body2="seg5" />
    <exclude body1="seg4" body2="seg6" />
    <exclude body1="seg4" body2="seg7" />
    <exclude body1="seg4" body2="seg8" />
    <exclude body1="seg5" body2="seg6" />
    <exclude body1="seg5" body2="seg7" />
    <exclude body1="seg5" body2="seg8" />
    <exclude body1="seg6" body2="seg7" />
    <exclude body1="seg6" body2="seg8" />
    <exclude body1="seg7" body2="seg8" />
    </contact>
</mujoco>
